# cluster-scheduler请求审计服务失败后导致后续请求一直失败, 且报错信息相同

## 原因

`AsyncAuditService`中的`asyncAudit`方法复用了CoroutineScope, 导致后续请求失败后, 该CoroutineScope被取消, 从而导致后续请求一直失败
该代码如下

```kotlin
class AsyncAuditService(private val auditService: AuditService) : AuditService, LogCapability {

	private val coroutineScope = CoroutineScope(Dispatchers.IO)

	private fun asyncAudit(
		successLog: String,
		failureLog: String,
		doAudit: suspend CoroutineScope.() -> Unit,
	) {
		coroutineScope.launch { doAudit() }.invokeOnCompletion {
			if (it != null)
				logger.warn(failureLog, it)
			else
				logger.info(successLog)
		}
	}

}
```

## 解决方案

为每个请求创建一个CoroutineScope, 修改后的代码如下

```kotlin
class AsyncAuditService(private val auditService: AuditService) : AuditService, LogCapability {

	private fun asyncAudit(
		successLog: String,
		failureLog: String,
		doAudit: suspend CoroutineScope.() -> Unit,
	) {
		CoroutineScope(Dispatchers.IO).launch { doAudit() }.invokeOnCompletion {
			if (it != null)
				logger.warn(failureLog, it)
			else
				logger.info(successLog)
		}
	}

}
```

## 参考

- [CoroutineScope](https://kotlinlang.org/api/kotlinx.coroutines/kotlinx-coroutines-core/kotlinx.coroutines/-coroutine-scope/)
- [CoroutineScope cannot be reused after an exception thrown](https://stackoverflow.com/questions/59996928/coroutinescope-cannot-be-reused-after-an-exception-thrown)